Workbook

Sheet Start here
A1: Signal School – manual testing
A2: Read the PDF guide first (Signal-School-QA-Guide.pdf). It explains the school, the app and how to test.
A4: How to use this file
A5: 1. Go to the sheet "Test cases". Do the tests from top to bottom (some tests use what an earlier test did).
A6: 2. For each row: log in as the person in "Who logs in" (see sheet "Logins"), follow "Steps", use "Test data".
A7: 3. Compare what you see with "Expected result". Choose a Status: Pass, Fail, Blocked or Skipped.
A8: 4. Write anything odd in "Comments" – even small things (a word cut off, a slow page, a confusing button).
A9: 5. For every Fail, add a row in the sheet "Bugs" with a screenshot name. Put the screenshots in one folder.
A10: 6. The sheet "Summary" counts Pass / Fail automatically.
A12: Status meaning
A13: Pass – works as written. Fail – something is different or broken. Blocked – could not test (e.g. earlier step failed).
A14: Skipped – not tested on purpose (write why). Not run – not done yet.
... A21: • Never use real children's names, photos or phone numbers while testing.

Sheet Test cases
A1: ID | B1: Area | C1: Who logs in | D1: Device | E1: Where (screen / path) | F1: Steps | G1: Test data | H1: Expected result | I1: Priority | J1: Status | K1: Comments | L1: Tested on (date) | M1: Tester
A2: LG-01 | B2: Login | C2: — | D2: Phone | E2: Open the app link | F2: Open the link for the first time. Tap "मराठी", then "हिंदी", then "ગુજરાતી", then "English". | H2: The login screen changes language each time you tap. Logo, "Signal School" and the Log in box are visible without zooming. | I2: High | J2: Not run
A3: LG-02 | B3: Login | C3: Teacher (email) | D3: Phone | E3: Login screen | F3: Type the email and password, tap "Log in". | G3: sunita@demo.test / password123 | H3: Opens the "Today" page with "Namaste, Sunita". | I3: High | J3: Not run
A4: LG-03 | B4: Login | C4: Teacher (mobile) | D4: Phone | E4: Login screen | F4: Log out. Log in with the mobile number instead of email. | G4: 9820000004 / password123 | H4: Opens the "Today" page with "Namaste, Sunita". | I4: High | J4: Not run
A5: LG-04 | B5: Login | C5: Teacher | D5: Phone | E5: Login screen | F5: Type a wrong password and tap "Log in". | G5: sunita@demo.test / wrong123 | H5: Red message "Wrong mobile number/email or password". You stay on the login screen. | I5: High | J5: Not run
A6: LG-05 | B6: Login | C6: — | D6: Phone | E6: Login screen | F6: Leave both boxes empty and tap "Log in". | H6: You are not logged in. The empty boxes are marked as needed. | I6: Medium | J6: Not run
A7: LG-06 | B7: Login | C7: — | D7: Phone | E7: Login screen | F7: Type a password. Tap the eye icon, then tap it again. | G7: any | H7: The password shows as letters, then hides again as dots. | I7: Low | J7: Not run
A8: LG-07 | B8: Login | C8: Inactive teacher | D8: Phone | E8: Login screen | F8: Log in with the inactive account. | G8: inactive@demo.test / password123 | H8: Message "This account is inactive. Contact the school office." Not logged in. | I8: High | J8: Not run
A9: LG-08 | B9: Login | C9: New teacher | D9: Phone | E9: Login → Welcome page | F9: Log in with the temporary password. On "Welcome, Neha Joshi" type current password, then a new password and a DIFFERENT one in "Type the new password again". Tap "Change password". | G9: newteacher@demo.test / Welcome@123; new: NehaQa@2026; again: NehaQa@2027 | H9: Message "Passwords do not match". Password is not changed. | I9: High | J9: Not run
A10: LG-09 | B10: Login | C10: New teacher | D10: Phone | E10: Welcome page | F10: Now type a short new password (both boxes the same) and tap "Change password". | G10: new: abc12 | H10: Message "At least 8 characters". Password is not changed. | I10: Medium | J10: Not run
A11: LG-10 | B11: Login | C11: New teacher | D11: Phone | E11: Welcome page | F11: Type the right values and tap "Change password". | G11: current: Welcome@123; new and again: NehaQa@2026 | H11: "Password changed". The Today page opens and says "No class is assigned to you yet". Log out and log in with NehaQa@2026: works. | I11: High | J11: Not run
A12: LG-11 | B12: Login | C12: Teacher | D12: Phone | E12: Me → Log out | F12: Tap "More" → "Me" → "Log out" → confirm "Log out". Then press the phone's Back button. | H12: The login screen opens. Back does not show the app pages again. | I12: High | J12: Not run
A13: LG-12 | B13: Login | C13: Teacher | D13: Phone | E13: Any page | F13: Log in, close the browser tab completely, open the app link again. | H13: You are still logged in (no need to type the password again). | I13: Medium | J13: Not run
A14: LG-13 | B14: Login | C14: Teacher | D14: Computer | E14: Login screen | F14: Type a wrong password 10 times for Pooja (pooja@demo.test). Then type the right password. | G14: pooja@demo.test / wrong… then password123 | H14: After 10 wrong tries: "Too many wrong attempts. Try again after 15 minutes." The right password also waits 15 minutes. | I14: Low | J14: Not run
A15: TC-01 | B15: Teacher – Today | C15: Teacher | D15: Phone | E15: Today | F15: Log in as Sunita. Look at the Today page. | G15: sunita@demo.test | H15: Shows "Namaste, Sunita", today's date, "Attendance is waiting in 1 class", class card "Std 1 A – Attendance not taken yet" with a big "Take attendance" button, and "My subjects" with progress bars. | I15: High | J15: Not run
A16: TC-02 | B16: Teacher – Today | C16: Teacher | D16: Phone | E16: Bottom bar | F16: Tap each item of the bottom bar: Today, Attendance, Students, Syllabus, More. | H16: Each opens its page. "More" opens a small sheet with "Marks" and "Me". The bar stays at the bottom and never hides buttons. | I16: High | J16: Not run
A17: TC-03 | B17: Teacher – Attendance | C17: Teacher | D17: Phone | E17: Today → Take attendance | F17: Tap "Take attendance" on Std 1 A. | H17: List of all Std 1 A children with roll numbers. Everyone starts on P (green). Counts show "Present: (all) · Absent: 0 · Leave: 0". A short help note is shown. | I17: High | J17: Not run
A18: TC-04 | B18: Teacher – Attendance | C18: Teacher | D18: Phone | E18: Take attendance | F18: Tap "A" for Aryan Mhatre and "L" for Riya Kale. | G18: Aryan Mhatre, Riya Kale | H18: Aryan's row turns red (A), Riya's turns yellow (L). Counts change at once: Absent 1, Leave 1. | I18: High | J18: Not run
A19: TC-05 | B19: Teacher – Attendance | C19: Teacher | D19: Phone | E19: Take attendance | F19: Type a name in the "Search" box above the list. Then clear it. | G19: Riya | H19: Only Riya Kale is listed. After clearing, all children are back with your marks kept. | I19: Medium | J19: Not run
A20: TC-06 | B20: Teacher – Attendance | C20: Teacher | D20: Phone | E20: Take attendance | F20: Tap "Save attendance". | H20: Message "Attendance saved: … present, 1 absent". Today page now shows Std 1 A in green "Attendance done: … present (time)" and the button says "Change attendance". | I20: High | J20: Not run
A21: TC-07 | B21: Teacher – Attendance | C21: Teacher | D21: Phone | E21: Today → Change attendance | F21: Open it again. Change Aryan to P. Do not save yet. | H21: A note says "You changed some marks. Press Save attendance to keep them." After "Save attendance" the new counts are saved. | I21: High | J21: Not run
A22: TC-08 | B22: Teacher – Attendance | C22: Teacher | D22: Phone | E22: Take attendance | F22: Mark 2 children A, then tap "Mark everyone present". | H22: Everyone is back on P. Counts show Absent 0. | I22: Medium | J22: Not run
A23: TC-09 | B23: Teacher – Attendance | C23: Teacher | D23: Phone | E23: Take attendance → Date | F23: Change the date to yesterday. | G23: yesterday | H23: Yesterday's saved attendance of Std 1 A is shown and can be changed and saved. | I23: Medium | J23: Not run
A24: TC-10 | B24: Teacher – Attendance | C24: Teacher | D24: Phone | E24: Take attendance → Date | F24: Change the date to a day 10 days ago. | G24: 10 days ago | H24: Warning "This date is too old to change. Ask the principal." The buttons cannot be changed and there is no Save button. | I24: High | J24: Not run
A25: TC-11 | B25: Teacher – Attendance | C25: Teacher | D25: Phone | E25: Take attendance → Date | F25: Try to pick tomorrow's date. | G25: tomorrow | H25: Not allowed: warning "You cannot choose a future date" (or the date cannot be picked). | I25: Medium | J25: Not run
A26: TC-12 | B26: Teacher – Attendance | C26: Teacher | D26: Phone | E26: Take attendance (no internet) | F26: Turn ON Airplane mode. Change one mark and tap "Save attendance". Then turn Airplane mode OFF and wait 1 minute. | H26: With no internet: "No internet. Attendance is saved on this phone and will be sent automatically…". After internet returns, the waiting message goes away and the change is saved (check it on a computer). | I26: High | J26: Not run
A27: TC-13 | B27: Teacher – Diary | C27: Teacher | D27: Phone | E27: Today → Class diary | F27: Tap "Class diary" on Std 1 A. Write a note and save. | G27: Today we learned numbers 1 to 20. | H27: "Diary saved". The note shows with today's date and "by Sunita Patil". | I27: Medium | J27: Not run
A28: TC-14 | B28: Teacher – Students | C28: Teacher | D28: Phone | E28: Today → Students | F28: Tap "Students" on the Std 1 A card. | H28: The Std 1 A class list opens with photos (or initials), roll numbers and today's mark. | I28: Medium | J28: Not run
A29: TC-15 | B29: Teacher – Students | C29: Teacher | D29: Phone | E29: Students → search | F29: Type in the search box. | G29: Riya | H29: Riya Kale appears (Std 1 A). | I29: High | J29: Not run
A30: TC-16 | B30: Teacher – Students | C30: Teacher | D30: Phone | E30: Students → search | F30: Search by the parent's mobile number. | G30: 9123400004 | H30: Kiran Thakur appears. | I30: Medium | J30: Not run
A31: TC-17 | B31: Teacher – Student profile | C31: Teacher | D31: Phone | E31: Students → Riya Kale | F31: Open Riya Kale. | H31: Photo, "Std 1 A", Roll no., GR number, age, "Sunil Kale · Father" with call and WhatsApp icons, and tabs: Details, Daily diary, Past years, Report card, Health. "Attendance this month" shows a small calendar with totals. | I31: High | J31: Not run
A32: TC-18 | B32: Teacher – Student profile | C32: Teacher | D32: Phone | E32: Riya Kale → Past years | F32: Open the "Past years" tab. | H32: Shows last year: Balwadi A, "Moved to next class", with that year's attendance. | I32: Medium | J32: Not run
A33: TC-19 | B33: Teacher – Student profile | C33: Teacher | D33: Phone | E33: Riya Kale → Daily diary | F33: Add a note about the child and save. | G33: Riya read a full story today. | H33: Note appears at the top with today's date and "by Sunita Patil". | I33: Medium | J33: Not run
A34: TC-20 | B34: Teacher – Student profile | C34: Teacher | D34: Phone | E34: Riya Kale → call / WhatsApp | F34: Tap the phone icon. Go back. Tap the WhatsApp icon. | H34: Phone dialer opens with 9123400001. WhatsApp opens a chat to that number (if WhatsApp is installed). | I34: Medium | J34: Not run
A35: TC-21 | B35: Teacher – Student profile | C35: Teacher | D35: Phone | E35: Aryan Mhatre → camera icon | F35: Open Aryan Mhatre (no photo). Tap the camera icon on the picture, choose the photo file. | G35: test-files/child-photo-boy.jpg | H35: The photo shows on the profile and in the class list. | I35: High | J35: Not run
A36: TC-22 | B36: Teacher – Student profile | C36: Teacher | D36: Phone | E36: Aryan Mhatre → camera icon | F36: Try to upload the wrong files as a photo. | G36: not-a-photo.pdf, then photo-too-big-9MB.png | H36: PDF: "This file type is not allowed" (or it cannot be picked). Big file: "The file is too large". The old photo stays. | I36: Medium | J36: Not run
A37: TC-23 | B37: Teacher – Student profile | C37: Teacher | D37: Phone | E37: Riya Kale → Edit | F37: Tap "Edit", change the address, tap "Save student". | G37: New address: Kopri, Thane | H37: "Saved". Details tab shows the new address. | I37: Medium | J37: Not run
A38: TC-24 | B38: Teacher – Student profile | C38: Teacher | D38: Phone | E38: Riya Kale → Health | F38: Add a health check-up: today's date, height and weight. Save. | G38: Height 112, Weight 19 | H38: The check-up shows in the list with "Height: 112 cm", "Weight: 19 kg". | I38: Medium | J38: Not run
A39: TC-25 | B39: Teacher – Students | C39: Teacher | D39: Phone | E39: Students → Add student | F39: Tap "Add student". Fill name, class, gender. Tap "Save student". | G39: QA Child One, Std 1 A, Girl | H39: Message "QA Child One added with register number SS-…". The child is in the Std 1 A list. | I39: High | J39: Not run
A40: TC-26 | B40: Teacher – Students | C40: Teacher | D40: Phone | E40: Students → Add student | F40: Add a child with the same name and parent mobile as an existing child. | G40: Riya Kale, Std 1 A, mobile 9123400001 | H40: Question "Is this child already in the school records?" shows Riya Kale. Tap Cancel: nothing is added. | I40: High | J40: Not run
...

Sheet Logins
A1: Role | B1: Name | C1: Email | D1: Mobile | E1: Password | F1: What to use it for
A2: Teacher | B2: Sunita Patil | C2: sunita@demo.test | D2: 9820000004 | E2: password123 | F2: Class teacher of Std 1 A. Std 1 A attendance is not taken today.
A3: Teacher | B3: Rahul Verma | C3: rahul@demo.test | D3: 9820000005 | E3: password123 | F3: Class teacher of Std 5 A; teaches Maths and English in Std 5, 6, 7.
A4: Teacher | B4: Kavita Jadhav | C4: kavita@demo.test | D4: 9820000006 | E4: password123 | F4: Class teacher of Std 2 A and Std 3 A. Std 3 A attendance is not taken today.
A5: New teacher | B5: Neha Joshi | C5: newteacher@demo.test | D5: 9820000011 | E5: Welcome@123 (temporary) | F5: Logs in for the first time: must choose a new password. No class yet.
A6: Inactive teacher | B6: Deepak Rane | C6: inactive@demo.test | D6: 9820000012 | E6: password123 | F6: Made inactive: must NOT be able to log in.
A7: Office clerk | B7: Ganesh Pawar | C7: clerk@demo.test | D7: 9820000003 | E7: password123 | F7: Admits children, imports, health, leaving certificates. Cannot take attendance.
A8: Principal | B8: Anita Deshmukh | C8: principal@demo.test | D8: 9820000002 | E8: password123 | F8: Runs Signal Shala, Thane: everything in that school.
A9: Trust owner | B9: Meera Kulkarni | C9: owner@demo.test | D9: 9820000001 | E9: password123 | F9: Sees both schools (Thane and Nerul). Can add schools.
A10: Teacher (2nd school) | B10: Imran Shaikh | C10: imran@demo.test | D10: 9820000010 | E10: password123 | F10: Teacher at Signal Shala, Nerul (that school uses the "Marigold" look).

Sheet Test data
A1: Child | B1: Class | C1: About | D1: Used for
A2: Riya Kale | B2: Std 1 A | C2: Girl, has a photo. Parent Sunil Kale, 9123400001. Was in Balwadi A last year. | D2: Search, profile, attendance, diary, health, past years
A3: Aryan Mhatre | B3: Std 1 A | C3: Boy, NO photo. Parent Kavita Mhatre, 9123400002. | D3: Adding a photo
A4: Ishaan Jagtap | B4: Std 2 A | C4: Boy. His birthday is TODAY. | D4: Birthday line on the Dashboard
A5: Swati Gholap | B5: Std 2 A | C5: Girl. Last health check-up: "needs a doctor again" (eyes). | D5: Health follow-up
A6: Nikhil Sonawane | B6: Std 3 A | C6: Boy, studying. | D6: Mark as left school + leaving certificate
A7: Kiran Thakur | B7: Std 4 A | C7: Girl. Absent the last 5 school days, low attendance. | D7: Dashboard: "Absent several days in a row" and "Children who often miss school"
A8: Lata Bhalerao | B8: Std 2 A (last year) | C8: Girl. Left school last year (family moved away). | D8: "Search all years" and Re-admit
A10: File (folder test-files) | B10: What it is | C10: Used for
A11: child-photo-girl.jpg | B11: A drawn photo of a girl | C11: Add / change a child's photo
A12: child-photo-boy.jpg | B12: A drawn photo of a boy | C12: Add a photo for Aryan Mhatre
A13: teacher-photo.jpg | B13: A drawn photo of a woman | C13: Your own photo on the "Me" page
A14: school-logo.png | B14: A sample school logo | C14: School settings: Upload school logo
A15: photo-too-big-9MB.png | B15: A picture larger than 8 MB | C15: Must be refused: "The file is too large"
A16: not-a-photo.pdf | B16: A PDF, not a picture or sheet | C16: Must be refused: "This file type is not allowed"
A17: students-import-5-good.xlsx | B17: 5 correct children | C17: Import: all 5 rows ready
A18: students-import-with-errors.xlsx | B18: 5 rows: 1 correct, 4 with mistakes | C18: Import: 1 ready, 4 show problems
A19: students-import-3-rows.csv | B19: 3 correct children (CSV file) | C19: Import from a CSV file
A21: Schools: Signal Shala, Thane (Balwadi to Std 7, look "Signal Shala") and Signal Shala, Nerul (Balwadi to Std 2, look "Marigold").
A22: Every day counts as a school day in the test data, so attendance can be tested any day of the week.

Sheet Bugs
A1: Bug no. | B1: Test case ID | C1: Screen | D1: What happened | E1: What should happen | F1: Steps to see it again | G1: Phone / Computer (model, browser) | H1: Screenshot file | I1: How bad (Blocker / Major / Minor / Cosmetic) | J1: Date | K1: Fixed? (for developer)
A2: 1
A3: 2
A4: 3
A5: 4
A6: 5
A7: 6
A8: 7
A9: 8
A10: 9
A11: 10
A12: 11
A13: 12
... A41: 40

Sheet Summary
A1: Area | B1: Total | C1: Pass | D1: Fail | E1: Blocked | F1: Skipped | G1: Not run
A2: Login | B2: =COUNTIF('Test cases'!$B$2:$B$117,"Login*") | C2: =COUNTIFS('Test cases'!$B$2:$B$117,"Login*",'Test cases'!$J$2:$J$117,"Pass") | D2: =COUNTIFS('Test cases'!$B$2:$B$117,"Login*",'Test cases'!$J$2:$J$117,"Fail") | E2: =COUNTIFS('Test cases'!$B$2:$B$117,"Login*",'Test cases'!$J$2:$J$117,"Blocked") | F2: =COUNTIFS('Test cases'!$B$2:$B$117,"Login*",'Test cases'!$J$2:$J$117,"Skipped") | G2: =COUNTIFS('Test cases'!$B$2:$B$117,"Login*",'Test cases'!$J$2:$J$117,"Not run")
A3: Teacher | B3: =COUNTIF('Test cases'!$B$2:$B$117,"Teacher*") | C3: =COUNTIFS('Test cases'!$B$2:$B$117,"Teacher*",'Test cases'!$J$2:$J$117,"Pass") | D3: =COUNTIFS('Test cases'!$B$2:$B$117,"Teacher*",'Test cases'!$J$2:$J$117,"Fail") | E3: =COUNTIFS('Test cases'!$B$2:$B$117,"Teacher*",'Test cases'!$J$2:$J$117,"Blocked") | F3: =COUNTIFS('Test cases'!$B$2:$B$117,"Teacher*",'Test cases'!$J$2:$J$117,"Skipped") | G3: =COUNTIFS('Test cases'!$B$2:$B$117,"Teacher*",'Test cases'!$J$2:$J$117,"Not run")
A4: Office clerk | B4: =COUNTIF('Test cases'!$B$2:$B$117,"Office clerk*") | C4: =COUNTIFS('Test cases'!$B$2:$B$117,"Office clerk*",'Test cases'!$J$2:$J$117,"Pass") | D4: =COUNTIFS('Test cases'!$B$2:$B$117,"Office clerk*",'Test cases'!$J$2:$J$117,"Fail") | E4: =COUNTIFS('Test cases'!$B$2:$B$117,"Office clerk*",'Test cases'!$J$2:$J$117,"Blocked") | F4: =COUNTIFS('Test cases'!$B$2:$B$117,"Office clerk*",'Test cases'!$J$2:$J$117,"Skipped") | G4: =COUNTIFS('Test cases'!$B$2:$B$117,"Office clerk*",'Test cases'!$J$2:$J$117,"Not run")
A5: Principal | B5: =COUNTIF('Test cases'!$B$2:$B$117,"Principal*") | C5: =COUNTIFS('Test cases'!$B$2:$B$117,"Principal*",'Test cases'!$J$2:$J$117,"Pass") | D5: =COUNTIFS('Test cases'!$B$2:$B$117,"Principal*",'Test cases'!$J$2:$J$117,"Fail") | E5: =COUNTIFS('Test cases'!$B$2:$B$117,"Principal*",'Test cases'!$J$2:$J$117,"Blocked") | F5: =COUNTIFS('Test cases'!$B$2:$B$117,"Principal*",'Test cases'!$J$2:$J$117,"Skipped") | G5: =COUNTIFS('Test cases'!$B$2:$B$117,"Principal*",'Test cases'!$J$2:$J$117,"Not run")
A6: Trust owner | B6: =COUNTIF('Test cases'!$B$2:$B$117,"Trust owner*") | C6: =COUNTIFS('Test cases'!$B$2:$B$117,"Trust owner*",'Test cases'!$J$2:$J$117,"Pass") | D6: =COUNTIFS('Test cases'!$B$2:$B$117,"Trust owner*",'Test cases'!$J$2:$J$117,"Fail") | E6: =COUNTIFS('Test cases'!$B$2:$B$117,"Trust owner*",'Test cases'!$J$2:$J$117,"Blocked") | F6: =COUNTIFS('Test cases'!$B$2:$B$117,"Trust owner*",'Test cases'!$J$2:$J$117,"Skipped") | G6: =COUNTIFS('Test cases'!$B$2:$B$117,"Trust owner*",'Test cases'!$J$2:$J$117,"Not run")
A7: Looks | B7: =COUNTIF('Test cases'!$B$2:$B$117,"Looks*") | C7: =COUNTIFS('Test cases'!$B$2:$B$117,"Looks*",'Test cases'!$J$2:$J$117,"Pass") | D7: =COUNTIFS('Test cases'!$B$2:$B$117,"Looks*",'Test cases'!$J$2:$J$117,"Fail") | E7: =COUNTIFS('Test cases'!$B$2:$B$117,"Looks*",'Test cases'!$J$2:$J$117,"Blocked") | F7: =COUNTIFS('Test cases'!$B$2:$B$117,"Looks*",'Test cases'!$J$2:$J$117,"Skipped") | G7: =COUNTIFS('Test cases'!$B$2:$B$117,"Looks*",'Test cases'!$J$2:$J$117,"Not run")
A8: General | B8: =COUNTIF('Test cases'!$B$2:$B$117,"General*") | C8: =COUNTIFS('Test cases'!$B$2:$B$117,"General*",'Test cases'!$J$2:$J$117,"Pass") | D8: =COUNTIFS('Test cases'!$B$2:$B$117,"General*",'Test cases'!$J$2:$J$117,"Fail") | E8: =COUNTIFS('Test cases'!$B$2:$B$117,"General*",'Test cases'!$J$2:$J$117,"Blocked") | F8: =COUNTIFS('Test cases'!$B$2:$B$117,"General*",'Test cases'!$J$2:$J$117,"Skipped") | G8: =COUNTIFS('Test cases'!$B$2:$B$117,"General*",'Test cases'!$J$2:$J$117,"Not run")
A9: All tests | B9: =COUNTA('Test cases'!$J$2:$J$117) | C9: =COUNTIF('Test cases'!$J$2:$J$117,"Pass") | D9: =COUNTIF('Test cases'!$J$2:$J$117,"Fail") | E9: =COUNTIF('Test cases'!$J$2:$J$117,"Blocked") | F9: =COUNTIF('Test cases'!$J$2:$J$117,"Skipped") | G9: =COUNTIF('Test cases'!$J$2:$J$117,"Not run")
